<?xml version="1.0" ?>
<robot name="solo12" xmlns:xacro="http://ros.org/wiki/xacro">
    
    <material name="black">
    <color rgba="0.0 0.0 0.0 1.0"/>
  </material>
  <material name="blue">
    <color rgba="0.0 0.0 0.8 1.0"/>
  </material>
  <material name="green">
    <color rgba="0.0 0.8 0.0 1.0"/>
  </material>
  <material name="grey">
    <color rgba="0.2 0.2 0.2 1.0"/>
  </material>
  <material name="silver">
    <color rgba="0.913725490196 0.913725490196 0.847058823529 1.0"/>
  </material>
  <material name="orange">
    <!-- <color rgba="1.0 0.423529411765 0.0392156862745 1.0"/> -->
    <color rgba="0.12 0.15 0.2 1.0"/>
  </material>
  <material name="brown">
    <color rgba="0.870588235294 0.811764705882 0.764705882353 1.0"/>
  </material>
  <material name="red">
    <color rgba="0.8 0.0 0.0 1.0"/>
  </material>
  <material name="white">
    <color rgba="1.0 1.0 1.0 1.0"/>
  </material>

   <link name="base">
    <visual>
      <origin rpy="0 0 0" xyz="0 0 0"/>
      <geometry>
        <box size="0.001 0.001 0.001"/>
      </geometry>
    </visual>
    <inertial>
            <mass value="1.16115091"/>
            <origin xyz="0.0 0.0 0.0"/>
            <inertia ixx="0.00578574" ixy="0.0" ixz="0.0" iyy="0.01938108" iyz="0.0" izz="0.02476124"/>
        </inertial>
  </link>
    <joint name="floating_base" type="fixed">
        <origin rpy="0 0 0" xyz="0 0 0"/>
        <parent link="base"/>
        <child link="trunk"/>
      </joint>
    <link name="trunk">
        <visual>
            <origin rpy="1.5708 0 0" xyz="0 0 0"/>
            <geometry>
                <mesh filename="meshes/obj/solo12/solo_12_base.obj"/>
            </geometry>
        </visual>
        <!-- <collision>
            <geometry>
                <mesh filename="meshes/mini_body.obj"/>
            </geometry>
            <origin rpy="0 0 0" xyz="0 0 0"/>
        </collision> -->
        <collision>
          <origin rpy="0 0 0" xyz="0 0 0"/>
          <geometry>
            <box size="0.45 0.21 0.05"/>
          </geometry>
        </collision>
    </link>

    <!--!!!!!!!!!!!! Front Right Leg !!!!!!!!!!!!!!!!!!!!!!!!!!!!!!!!!!!!-->
    <joint name="FR_hip_joint" type="revolute">
        <axis xyz="1 0 0"/>
        <origin rpy="0 0 0" xyz="0.1946 -0.0875 0"/>
        <parent link="trunk"/>
        <child link="FR_hip"/>
        <dynamics damping="0" friction="0"/>
        <limit effort="3" lower="-1.6" upper="1.6" velocity="40"/>
    </joint>
    <link name="FR_hip">
        <inertial>
            <mass value="0.14853845"/>
            <origin rpy="0 0 0" xyz="-0.07870700 -0.01 0."/>
            <inertia ixx="0.00003024" ixy="-0.00004671" ixz="0.0" iyy="0.00041193" iyz="0.0" izz="0.00041107"/>
        </inertial>
        <visual>
            <origin rpy="1.5708 0 0" xyz="0.01950 0 0"/>
            <geometry>
                <mesh filename="./meshes/obj/solo12/solo12_hip_fe_fr.obj"/>
            </geometry>
        </visual>
	<!-- <collision>
            <geometry>
                <mesh filename="./meshes/obj/solo12/solo12_hip_fe_fr.obj"/>
            </geometry>
            <origin rpy="1.5708 0 0" xyz="0.01950 0 0"/>
	</collision> -->
    </link>

    <joint name="FR_thigh_joint" type="revolute">
        <axis xyz="0 1 0"/>
        <origin rpy="0 0 0" xyz="0 -0.014 0"/>
        <parent link="FR_hip"/>
        <child link="FR_thigh"/>
        <dynamics damping="0" friction="0"/>
        <limit effort="3" lower="-2.6" upper="2.6" velocity="40"/>
    </joint>
    <link name="FR_thigh">
        <inertial>
             <origin rpy="0 0 0" xyz="-0.00001377 -0.01935853 -0.07870700"/>
             <mass value="0.14853845"/>
             <inertia ixx="0.00041107" ixy="0.0" ixz="0.0" iyy="0.00041193" iyz="-0.00004671" izz="0.00003024"/>
        </inertial>
        <visual>
            <geometry>
                <mesh filename="meshes/obj/with_foot/solo_upper_leg_right_side.obj"/>
            </geometry>
            <origin rpy="0 0 0" xyz="0 0 0"/>
        </visual>
	<collision>
          <origin rpy="0 0 0" xyz="0 0 0"/>
          <geometry>
                 <mesh filename="meshes/obj/with_foot/solo_upper_leg_right_side.obj"/>
          </geometry>
	</collision> 
    </link>

    <joint name="FR_calf_joint" type="revolute">
        <axis xyz="0 1 0"/>
        <origin rpy="0 0 0" xyz="0 -0.03745 -0.16"/>
        <parent link="FR_thigh"/>
        <child link="FR_calf"/>
        <dynamics damping="0" friction="0"/>
        <limit effort="3" lower="-2.6" upper="2.6" velocity="40"/>
    </joint>
    <link name="FR_calf">
        <inertial>
            <origin rpy="0 0 0" xyz="0.0 0.00787644 -0.08928215"/>
            <mass value="0.03070001"/>
            <inertia ixx="0.00012024" ixy="0.0" ixz="0.0" iyy="0.00012029" iyz="-0.00000305" izz="0.00000216"/>
        </inertial>
        <visual>
            <geometry>
                <mesh filename="meshes/obj/with_foot/solo_lower_leg_right_side.obj"/>
            </geometry>
            <origin rpy="0 0 0" xyz="0 0 0"/>
        </visual>
	<!--- <collision>
            <geometry>
                <mesh filename="meshes/obj/with_foot/solo_lower_leg_right_side.obj"/>
            </geometry>
            <origin rpy="0 0 0" xyz="0 -0.008 -0.075"/>
	</collision>-->

    <!-- LOWER LEG LINK COLLISION -->
    <collision>
      <origin rpy="0 0 0" xyz="0 -0.008 -0.075"/>
      <geometry>
        <box size="0.016 0.016 0.17"/>
      </geometry>
    </collision>
    </link>

  <joint name="FR_ANKLE" type="fixed">
    <parent link="FR_calf"/>
    <child link="FR_foot"/>
    <origin rpy="0 0 0" xyz="0 -0.008 -0.16"/>
    <dynamics damping="0.0" friction="0.0"/>
  </joint>

  <link name="FR_foot">
    <!-- FOOT INERTIAL -->
    <!-- This link is symmetrical left or right -->
    <inertial>
      <origin rpy="0 0 0" xyz="0 0 0.00035767"/>
      <mass value="0.00693606"/>
      <inertia ixx="0.00000057" ixy="0.0" ixz="0.0" iyy="0.00000084" iyz="0.0" izz="0.00000053"/>
    </inertial>
    <!-- FOOT VISUAL -->
    <visual>
      <origin rpy="0 0 0" xyz="0 0 0"/>
      <geometry>
        <mesh filename="meshes/obj/with_foot/solo_foot.obj"/>
      </geometry>
    </visual>
    <!-- FOOT COLLISION -->
    <!-- <collision>
      <origin rpy="0 0 0" xyz="0 0 0"/>
      <geometry>
        <mesh filename="meshes/obj/with_foot/solo_foot.obj"/>
      </geometry>
    </collision> --!>
    <!-- FOOT COLLISION -->
    <collision>
      <origin rpy="0 0 0" xyz="0 0 0"/>
      <geometry>
        <sphere radius="0.015"/>
      </geometry>
    </collision>
  </link>


<!--!!!!!!!!!!!! Front Left Leg !!!!!!!!!!!!!!!!!!!!!!!!!!!!!!!!!!!!-->
    <joint name="FL_hip_joint" type="revolute">
        <axis xyz="1 0 0"/>
        <origin rpy="0 0 0" xyz="0.1946 0.0875 0"/>
        <parent link="trunk"/>
        <child link="FL_hip"/>
        <dynamics damping="0" friction="0"/>
        <limit effort="3" lower="-1.6" upper="1.6" velocity="40"/>
    </joint>
    <link name="FL_hip">
        <inertial>
            <mass value="0.14853845"/>
            <origin rpy="0 0 0" xyz="-0.07870700 0.01 0."/>
            <inertia ixx="0.00003024" ixy="0.00004671" ixz="0.0" iyy="0.00041193" iyz="0.0" izz="0.00041107"/>
        </inertial>
        <visual>
            <geometry>
                <mesh filename="meshes/obj/solo12/solo12_hip_fe_fl.obj"/>
            </geometry>
            <origin rpy="1.5708 0 0" xyz="0.01950 0 0"/>
        </visual>
	<!-- <collision>
            <geometry>
                <mesh filename="meshes/obj/solo12/solo12_hip_fe_fl.obj"/>
            </geometry>
            <origin rpy="1.5708 0 0" xyz="0.01950 0 0"/>
	</collision> -->
    </link>

    <joint name="FL_thigh_joint" type="revolute">
        <axis xyz="0 1 0"/>
        <origin rpy="0.0 0.0 0.0" xyz="0.0 0.014 0.00"/>
        <parent link="FL_hip"/>
        <child link="FL_thigh"/>
        <dynamics damping="0" friction="0"/>
        <limit effort="3" lower="-2.6" upper="2.6" velocity="40"/>
    </joint>
    <link name="FL_thigh">
        <inertial>
             <origin rpy="0 0 0" xyz="0.00001377 0.01935853 -0.07870700"/>
             <mass value="0.14853845"/>
             <inertia ixx="0.00041107" ixy="0.0" ixz="0.0" iyy="0.00041193" iyz="0.00004671" izz="0.00003024"/>
        </inertial>
        <visual>
            <geometry>
                <mesh filename="meshes/obj/with_foot/solo_upper_leg_left_side.obj"/>
            </geometry>
            <origin rpy="0 0 0" xyz="0 0 0"/>
        </visual>
	<collision>
          <origin rpy="0 0 0" xyz="0 0 0"/>
          <geometry>
            <mesh filename="meshes/obj/with_foot/solo_upper_leg_left_side.obj"/>
          </geometry>
	</collision> 
    </link>

    <joint name="FL_calf_joint" type="revolute">
        <axis xyz="0 1 0"/>
        <origin rpy="0 0 0" xyz="0 0.03745 -0.16"/>
        <parent link="FL_thigh"/>
        <child link="FL_calf"/>
        <dynamics damping="0" friction="0"/>
        <limit effort="3" lower="-2.6" upper="2.6" velocity="26"/>
    </joint>
    <link name="FL_calf">
        <inertial>
           <origin rpy="0 0 0" xyz="0.0 0.00787644 -0.08928215"/>
           <mass value="0.03070001"/>
           <inertia ixx="0.00012024" ixy="0.0" ixz="0.0" iyy="0.00012029" iyz="0.00000305" izz="0.00000216"/>
        </inertial>
        <visual>
            <geometry>
                <mesh filename="meshes/obj/with_foot/solo_lower_leg_left_side.obj"/>
            </geometry>
            <origin rpy="0 0 0" xyz="0 0 0"/>
        </visual>
	<!-- <collision>
            <geometry>
                <mesh filename="meshes/obj/with_foot/solo_lower_leg_left_side.obj"/>
            </geometry>
            <origin rpy="0 0 0" xyz="0 0.008 -0.075"/>
	</collision> -->
       <!-- LOWER LEG LINK COLLISION -->
       <collision>
         <origin rpy="0 0 0" xyz="0 0.008 -0.075"/>
         <geometry>
           <box size="0.016 0.016 0.17"/>
         </geometry>
       </collision>

    </link>

  <joint name="FL_ANKLE" type="fixed">
    <parent link="FL_calf"/>
    <child link="FL_foot"/>
    <origin rpy="0 0 0" xyz="0 0.008 -0.16"/>
    <dynamics damping="0.0" friction="0.0"/>
  </joint>

  <link name="FL_foot">
    <!-- FOOT INERTIAL -->
    <!-- This link is symmetrical left or right -->
    <inertial>
      <origin rpy="0 0 0" xyz="0 0 0.00035767"/>
      <mass value="0.00693606"/>
      <inertia ixx="0.00000057" ixy="0.0" ixz="0.0" iyy="0.00000084" iyz="0.0" izz="0.00000053"/>
    </inertial>
    <!-- FOOT VISUAL -->
    <visual>
      <origin rpy="0 0 0" xyz="0 0 0"/>
      <geometry>
        <mesh filename="meshes/obj/with_foot/solo_foot.obj"/>
      </geometry>
    </visual>
    <!-- FOOT COLLISION -->
    <!-- <collision>
      <origin rpy="0 0 0" xyz="0 0 0"/>
      <geometry>
        <mesh filename="meshes/obj/with_foot/solo_foot.obj"/>
      </geometry>
    </collision> -->
    <!-- FOOT COLLISION -->
    <collision>
      <origin rpy="0 0 0" xyz="0 0 0"/>
      <geometry>
        <sphere radius="0.015"/>
      </geometry>
    </collision>

  </link>
<!--!!!!!!!!!!!! Hind Right Leg !!!!!!!!!!!!!!!!!!!!!!!!!!!!!!!!!!!!-->
    <joint name="RR_hip_joint" type="revolute">
        <axis xyz="1 0 0"/>
        <origin rpy="0 0 0" xyz="-0.1946 -0.0875 0"/>
        <parent link="trunk"/>
        <child link="RR_hip"/>
        <dynamics damping="0" friction="0"/>
        <limit effort="3" lower="-1.6" upper="1.6" velocity="40"/>
    </joint>
    <link name="RR_hip">
        <inertial>
            <mass value="0.14853845"/>
            <origin rpy="0 0 0" xyz="0.07870700 -0.01 0."/>
            <inertia ixx="0.00003024" ixy="-0.00004671" ixz="0.0" iyy="0.00041193" iyz="0.0" izz="0.00041107"/>
        </inertial>
        <visual>
            <geometry>
                <mesh filename="meshes/obj/solo12/solo12_hip_fe_hr.obj"/>
            </geometry>
            <origin rpy="1.5708 0 0" xyz="-0.01950 0 0"/>
        </visual>
	<!-- <collision>
            <geometry>
                <mesh filename="meshes/obj/solo12/solo12_hip_fe_hr.obj"/>
            </geometry>
            <origin rpy="1.5708 0 0" xyz="-0.01950 0 0"/>
	</collision> -->
    </link>

    <joint name="RR_thigh_joint" type="revolute">
        <axis xyz="0 1 0"/>
        <origin rpy="0 0 0" xyz="0 -0.014 0"/>
        <parent link="RR_hip"/>
        <child link="RR_thigh"/>
        <dynamics damping="0" friction="0"/>
        <limit effort="3" lower="-2.6" upper="2.6" velocity="40"/>
    </joint>
    <link name="RR_thigh">
        <inertial>
           <origin rpy="0 0 0" xyz="-0.00001377 -0.01935853 -0.07870700"/>
           <mass value="0.14853845"/>
           <inertia ixx="0.00041107" ixy="0.0" ixz="0.0" iyy="0.00041193" iyz="-0.00004671" izz="0.00003024"/>
        </inertial>
        <visual>
            <geometry>
                <mesh filename="meshes/obj/with_foot/solo_upper_leg_right_side.obj"/>
            </geometry>
           <origin rpy="0.0 0.0 0.0" xyz="0.0 0.0 0.0"/>
        </visual>
	<collision>
            <geometry>
                <mesh filename="meshes/obj/with_foot/solo_upper_leg_right_side.obj"/>
            </geometry>
           <origin rpy="0.0 0.0 0.0" xyz="0.0 0.0 0.0"/>
	</collision> 
        <!-- <collision>
          <origin rpy="0 1.57079632679 0" xyz="0 0 -0.105"/>
          <geometry>
            <box size="0.17 0.015 0.030"/>
          </geometry>
        </collision> -->
    </link>

    <joint name="RR_calf_joint" type="revolute">
        <axis xyz="0 1 0"/>
        <origin rpy="0 0 0" xyz="0 -0.03745 -0.16"/>
        <parent link="RR_thigh"/>
        <child link="RR_calf"/>
        <dynamics damping="0" friction="0"/>
        <limit effort="3" lower="-2.6" upper="2.6" velocity="26"/>
    </joint>
    <link name="RR_calf">
        <inertial>
            <origin rpy="0 0 0" xyz="0.0 0.00787644 -0.08928215"/>
            <mass value="0.03070001"/>
            <inertia ixx="0.00012024" ixy="0.0" ixz="0.0" iyy="0.00012029" iyz="-0.00000305" izz="0.00000216"/>
        </inertial>
        <visual>
            <geometry>
                <mesh filename="meshes/obj/with_foot/solo_lower_leg_right_side.obj"/>
            </geometry>
            <origin rpy="0 0 0" xyz="0 0 0"/>
        </visual>
	<!-- <collision>
            <geometry>
                <mesh filename="meshes/obj/with_foot/solo_lower_leg_right_side.obj"/>
            </geometry>
            <origin rpy="0 0 0" xyz="0 -0.008 -0.075"/>
	</collision>-->
        <!-- LOWER LEG LINK COLLISION -->
        <collision>
          <origin rpy="0 0 0" xyz="0 -0.008 -0.075"/>
          <geometry>
            <box size="0.016 0.016 0.17"/>
          </geometry>
        </collision>
    </link>

  <joint name="RR_ANKLE" type="fixed">
    <parent link="RR_calf"/>
    <child link="RR_foot"/>
    <origin rpy="0 0 0" xyz="0 -0.008 -0.16"/>
    <dynamics damping="0.0" friction="0.0"/>
  </joint>

  <link name="RR_foot">
    <!-- FOOT INERTIAL -->
    <!-- This link is symmetrical left or right -->
    <inertial>
      <origin rpy="0 0 0" xyz="0 0 0.00035767"/>
      <mass value="0.00693606"/>
      <inertia ixx="0.00000057" ixy="0.0" ixz="0.0" iyy="0.00000084" iyz="0.0" izz="0.00000053"/>
    </inertial>
    <!-- FOOT VISUAL -->
    <visual>
      <origin rpy="0 0 0" xyz="0 0 0"/>
      <geometry>
        <mesh filename="meshes/obj/with_foot/solo_foot.obj"/>
      </geometry>
    </visual>
    <!-- FOOT COLLISION -->
    <!-- <collision>
      <origin rpy="0 0 0" xyz="0 0 0"/>
      <geometry>
        <mesh filename="meshes/obj/with_foot/solo_foot.obj"/>
      </geometry>
    </collision>-->
    <!-- FOOT COLLISION -->
    <collision>
      <origin rpy="0 0 0" xyz="0 0 0"/>
      <geometry>
        <sphere radius="0.015"/>
      </geometry>
    </collision>

  </link>
<!--!!!!!!!!!!!! Hind Left Leg !!!!!!!!!!!!!!!!!!!!!!!!!!!!!!!!!!!!-->
    <joint name="RL_hip_joint" type="revolute">
        <axis xyz="1 0 0"/>
        <origin rpy="0 0 0" xyz="-0.1946 0.0875 0"/>
        <parent link="trunk"/>
        <child link="RL_hip"/>
        <dynamics damping="0" friction="0"/>
        <limit effort="3" lower="-1.6" upper="1.6" velocity="40"/>
    </joint>
    <link name="RL_hip">
        <inertial>
            <mass value="0.14853845"/>
            <origin rpy="0 0 0" xyz="0.07870700 0.01 0."/>
            <inertia ixx="0.00003024" ixy="0.00004671" ixz="0.0" iyy="0.00041193" iyz="0.0" izz="0.00041107"/>
        </inertial>
        <visual>
            <geometry>
                <mesh filename="meshes/obj/solo12/solo12_hip_fe_hl.obj"/>
            </geometry>
            <origin rpy="1.5708 0 0" xyz="-0.01950 0 0"/>
        </visual>
	<!-- <collision>
            <geometry>
                <mesh filename="meshes/obj/solo12/solo12_hip_fe_hl.obj"/>
            </geometry>
            <origin rpy="1.5708 0 0" xyz="-0.01950 0 0"/>
	</collision> -->
    </link>

    <joint name="RL_thigh_joint" type="revolute">
        <axis xyz="0 1 0"/>
        <origin rpy="0 0 0" xyz="0 0.014 0"/>
        <parent link="RL_hip"/>
        <child link="RL_thigh"/>
        <dynamics damping="0" friction="0"/>
        <limit effort="3" lower="-2.6" upper="2.6" velocity="40"/>
    </joint>
    <link name="RL_thigh">
        <inertial>
             <origin rpy="0 0 0" xyz="0.00001377 0.01935853 -0.07870700"/>
             <mass value="0.14853845"/>
             <inertia ixx="0.00041107" ixy="0.0" ixz="0.0" iyy="0.00041193" iyz="0.00004671" izz="0.00003024"/>
        </inertial>
        <visual>
            <geometry>
                <mesh filename="meshes/obj/with_foot/solo_upper_leg_left_side.obj"/>
            </geometry>
            <origin rpy="0 0 0" xyz="0 0 0"/>
        </visual>
	<collision>
            <geometry>
                <mesh filename="meshes/obj/with_foot/solo_upper_leg_left_side.obj"/>
            </geometry>
            <origin rpy="0 0 0" xyz="0 0 0"/>
	</collision> 
	<!-- <collision>
          <origin rpy="0 1.57079632679 0" xyz="0 0 -0.105"/>
          <geometry>
            <box size="0.17 0.015 0.030"/>
          </geometry>
	</collision> -->
    </link>

    <joint name="RL_calf_joint" type="revolute">
        <axis xyz="0 1 0"/>
        <origin rpy="0 0 0" xyz="0 0.03745 -0.16"/>
        <parent link="RL_thigh"/>
        <child link="RL_calf"/>
        <dynamics damping="0" friction="0"/>
        <limit effort="3" lower="-2.6" upper="2.6" velocity="26"/>
    </joint>
    <link name="RL_calf">
        <inertial>
           <origin rpy="0 0 0" xyz="0.0 0.00787644 -0.08928215"/>
           <mass value="0.03070001"/>
           <inertia ixx="0.00012024" ixy="0.0" ixz="0.0" iyy="0.00012029" iyz="0.00000305" izz="0.00000216"/>
        </inertial>
        <visual>
            <geometry>
                <mesh filename="meshes/obj/with_foot/solo_lower_leg_left_side.obj"/>
            </geometry>
            <origin rpy="0 0 0" xyz="0 0 0"/>
        </visual>
	<!-- <collision>
            <geometry>
                <mesh filename="meshes/obj/with_foot/solo_lower_leg_left_side.obj"/>
            </geometry>
            <origin rpy="0 0 0" xyz="0 0 0"/>
	</collision> -->
        <!-- LOWER LEG LINK COLLISION -->
        <collision>
          <origin rpy="0 0 0" xyz="0 0.008 -0.075"/>
          <geometry>
            <box size="0.016 0.016 0.17"/>
          </geometry>
        </collision>
    </link>

  <joint name="RL_ANKLE" type="fixed">
    <parent link="RL_calf"/>
    <child link="RL_foot"/>
    <origin rpy="0 0 0" xyz="0 0.008 -0.16"/>
    <dynamics damping="0.0" friction="0.0"/>
  </joint>

  <link name="RL_foot">
    <!-- FOOT INERTIAL -->
    <!-- This link is symmetrical left or right -->
    <inertial>
      <origin rpy="0 0 0" xyz="0 0 0.00035767"/>
      <mass value="0.00693606"/>
      <inertia ixx="0.00000057" ixy="0.0" ixz="0.0" iyy="0.00000084" iyz="0.0" izz="0.00000053"/>
    </inertial>
    <!-- FOOT VISUAL -->
    <visual>
      <origin rpy="0 0 0" xyz="0 0 0"/>
      <geometry>
        <mesh filename="meshes/obj/with_foot/solo_foot.obj"/>
      </geometry>
    </visual>
    <!-- FOOT COLLISION -->
    <!-- <collision>
      <origin rpy="0 0 0" xyz="0 0 0"/>
      <geometry>
        <mesh filename="meshes/obj/with_foot/solo_foot.obj"/>
      </geometry>
    </collision>-->

    <collision>
      <origin rpy="0 0 0" xyz="0 0 0"/>
      <geometry>
        <sphere radius="0.015"/>
      </geometry>
    </collision>
  </link>
</robot>
